<mujocoinclude>
    <body name="base_chassis_link" pos="0 0 0.3">
        <!-- <joint name="object:joint" type="free" damping="0.01"></joint> -->

        <!-- <joint name="object:joint_x" type="slide" damping="0.0001" pos='0 0 0' axis='1 0 0'></joint>
        <joint name="object:joint_y" type="slide" damping="0.0001" pos='0 0 0' axis='0 1 0'></joint>
        <joint name="object:joint_z" type="slide" damping="0.0001" pos='0 0 0' axis='0 0 1'></joint> -->
        <!-- <joint name="object:joint_r" type="hinge" damping="0.0001" pos='0 0 0' axis='1 0 0'></joint>
        <joint name="object:joint_p" type="hinge" damping="0.0001" pos='0 0 0' axis='0 1 0'></joint>
        <joint name="object:joint_y" type="hinge" damping="0.0001" pos='0 0 0' axis='0 0 1'></joint> -->

        <inertial pos="0 0 0" mass="3.3" diaginertia="0.006837 0.027262 0.02987" />
        <geom size="0.165 0.05 0.035" type="box" rgba="0.3 0.3 0.3 1" />
        <geom size="0.085 0.05 0.025" pos="0 0.1 0" type="box" rgba="0.3 0.3 0.3 1" />
        <geom size="0.085 0.05 0.025" pos="0 -0.1 0" type="box" rgba="0.3 0.3 0.3 1" />

        <!-- <body name="chassis_right" pos="0 -0.1 0" quat="0.999048 -0.0436194 0 0"> -->
        <body name="chassis_right" pos="0 -0.1 0" quat="1 0 0 0">
            <!-- <inertial pos="0 0 0" mass="0.1" diaginertia="1 1 1" /> -->
            <inertial pos='0 0 0' mass='1.32' diaginertia='0.004147 0.040913 0.041840'/>
            <geom size="0.17 0.005 0.02" pos="0 0.035 0" type="box" rgba="0.65 0.65 0.75 1" />
            <geom size="0.17 0.005 0.02" pos="0 -0.035 0" type="box" rgba="0.65 0.65 0.75 1" />

            <!-- <body name="motor_front_rightR_link" pos="0.21 -0.025 0" quat="0.707123 0.70709 0 0"> -->
            <body name="motor_front_rightR_link" pos="0.21 -0.025 0" quat="0.7071067811865476 0.7071067811865476 0 0">

                <!-- <inertial pos="0 0 0" mass="0.25" diaginertia="1 1 1" /> -->
                <inertial pos="0 0 0" mass="0.072" diaginertia="0.00011397 0.00011397 0.00021765" />
                <joint name="motor_front_rightR_joint" pos="0 0 0" axis="0 0 1" damping='0.03' limited='true' range='-0.5 0.5'/>
                <geom size="0.0434 0.013" type="cylinder" rgba="1 1 1 1" />
                <body name="upper_leg_front_rightR_link" pos="0 -0.05 -0.03" quat="0.7071067811865476 -0.7071067811865476 0 0">
                    <!-- <inertial pos="0 0 0" mass="0.05" diaginertia="1 1 1" /> -->
                    <inertial pos="0 0 0" mass="0.24" diaginertia="0.00032459 0.00032637 0.000002178" />
                    <joint name="motor_front_rightR_extension" type='slide' pos="0 0 0" axis="0 0 -1"
                                        limited='true' range='0 0.2' damping='10'/>
                    <!-- <geom size="0.005 0.005 0.1" type="box" rgba="0.65 0.65 0.75 1" /> -->
                    <geom size="0.012 0.05" type="capsule" rgba="0.65 0.65 0.75 1" />
                </body>
            </body>

            <body name="motor_front_rightL_link" pos="0.21 0.04 0" quat="0.7071067811865476 0.7071067811865476 0 0">
                <inertial pos="0 0 0" mass="0.072" diaginertia="0.00011397 0.00011397 0.00021765" />
                <geom size="0.0434 0.013" type="cylinder" rgba="1 1 1 1" />
            </body>

            <body name="motor_back_rightR_link" pos="-0.21 -0.025 0" quat="0.7071067811865476 0.7071067811865476 0 0">
                <!-- <inertial pos="0 0 0" mass="0.25" diaginertia="1 1 1" /> -->
                <inertial pos="0 0 0" mass="0.072" diaginertia="0.00011397 0.00011397 0.00021765" />
                <joint name="motor_back_rightR_joint" pos="0 0 0" axis="0 0 1" damping='0.03'  limited='true' range='-0.5 0.5'/>
                <geom size="0.0434 0.013" type="cylinder" rgba="1 1 1 1" />
                <body name="upper_leg_back_rightR_link" pos="0 -0.05 -0.03" quat="0.7071067811865476 -0.7071067811865476 0 0">
                    <!-- <inertial pos="0 0 0" mass="0.05" diaginertia="1 1 1" /> -->
                    <inertial pos="0 0 0" mass="0.24" diaginertia="0.00032459 0.00032637 0.000002178" />
                    <joint name="motor_back_rightR_extension" type='slide' pos="0 0 0" axis="0 0 -1"
                                    limited='true' range='0 0.2' damping='10'/>
                    <!-- <geom size="0.005 0.005 0.1" type="box" rgba="0.65 0.65 0.75 1" /> -->
                    <geom size="0.012 0.05" type="capsule" rgba="0.65 0.65 0.75 1"/>
                </body>
            </body>

            <body name="motor_back_rightL_link" pos="-0.21 0.04 0" quat="0.7071067811865476 0.7071067811865476 0 0">
                <inertial pos="0 0 0" mass="0.072" diaginertia="0.00011397 0.00011397 0.00021765" />
                <geom size="0.0434 0.013" type="cylinder" rgba="1 1 1 1" />
            </body>

        </body>

        <!-- <body name="chassis_left" pos="0 0.1 0" quat="0.999048 0.0436194 0 0"> -->
        <body name="chassis_left" pos="0 0.1 0" quat="1 0 0 0">
            <!-- <inertial pos="0 0 0" mass="0.1" diaginertia="1 1 1" /> -->
            <inertial pos='0 0 0' mass='1.32' diaginertia='0.004147 0.040913 0.041840' />
            <geom size="0.17 0.005 0.02" pos="0 0.035 0" type="box" rgba="0.65 0.65 0.75 1" />
            <geom size="0.17 0.005 0.02" pos="0 -0.035 0" type="box" rgba="0.65 0.65 0.75 1" />

            <body name="motor_front_leftL_link" pos="0.21 0.025 0" quat="0.7071067811865476 0.7071067811865476 0 0">
                <!-- <inertial pos="0 0 0" mass="0.25" diaginertia="1 1 1" /> -->
                <inertial pos="0 0 0" mass="0.072" diaginertia="0.00011397 0.00011397 0.00021765" />

                <joint name="motor_front_leftL_joint" pos="0 0 0" axis="0 0 1" damping='0.03'  limited='true' range='-0.5 0.5'/>
                <geom size="0.0434 0.013" type="cylinder" rgba="1 1 1 1" />
                <body name="upper_leg_front_leftL_link" pos="0 -0.05 0.03" quat="0.7071067811865476 -0.7071067811865476 0 0">
                    <!-- <inertial pos="0 0 0" mass="0.05" diaginertia="1 1 1" /> -->
                    <inertial pos="0 0 0" mass="0.24" diaginertia="0.00032459 0.00032637 0.000002178" />

                    <joint name="motor_front_leftL_extension" type='slide' pos="0 0 0" axis="0 0 -1"
                                    limited='true' range='0 0.2' damping='10'/>
                    <!-- <geom size="0.005 0.005 0.1" type="box" rgba="0.65 0.65 0.75 1" /> -->
                    <geom size="0.012 0.05" type="capsule" rgba="0.65 0.65 0.75 1" />
                    <!-- <geom size="0.012" fromto="0 0 0 0 0 0.3" type="capsule" rgba="0.65 0.65 0.75 1" /> -->

                </body>
            </body>

            <body name="motor_front_leftR_link" pos="0.21 -0.04 0" quat="0.7071067811865476 0.7071067811865476 0 0">
                <inertial pos="0 0 0" mass="0.072" diaginertia="0.00011397 0.00011397 0.00021765" />
                <geom size="0.0434 0.013" type="cylinder" rgba="1 1 1 1" />
            </body>

            <body name="motor_back_leftL_link" pos="-0.21 0.025 0" quat="0.7071067811865476 0.7071067811865476 0 0">
                <!-- <inertial pos="0 0 0" mass="0.25" diaginertia="1 1 1" /> -->
                <inertial pos="0 0 0" mass="0.072" diaginertia="0.00011397 0.00011397 0.00021765" />

                <joint name="motor_back_leftL_joint" pos="0 0 0" axis="0 0 1" damping='0.03' limited='true' range='-0.5 0.5'/>
                <geom size="0.0434 0.013" type="cylinder" rgba="1 1 1 1" />
                <body name="upper_leg_back_leftL_link" pos="0 -0.05 0.03" quat="0.7071067811865476 -0.7071067811865476 0 0">
                    <!-- <inertial pos="0 0 0" mass="0.05" diaginertia="1 1 1" /> -->
                    <inertial pos="0 0 0" mass="0.24" diaginertia="0.00032459 0.00032637 0.000002178" />

                    <joint name="motor_back_leftL_extension" type='slide' pos="0 0 0" axis="0 0 -1"
                                    limited='true' range='0 0.2' damping='0.1'/>
                    <!-- <geom size="0.005 0.005 0.1" type="box" rgba="0.65 0.65 0.75 1" /> -->
                    <geom size="0.012 0.05" type="capsule" rgba="0.65 0.65 0.75 1" />
                </body>
            </body>

            <body name="motor_back_leftR_link" pos="-0.21 -0.04 0" quat="0.7071067811865476 0.7071067811865476 0 0">
                <inertial pos="0 0 0" mass="0.072" diaginertia="0.00011397 0.00011397 0.00021765" />
                <geom size="0.0434 0.013" type="cylinder" rgba="1 1 1 1" />
            </body>


        </body>
    </body>
</mujocoinclude>
